[2024-07-28T13:01:55.527+0000] {local_task_job_runner.py:120} INFO - ::group::Pre task execution logs
[2024-07-28T13:01:55.566+0000] {taskinstance.py:2076} INFO - Dependencies all met for dep_context=non-requeueable deps ti=<TaskInstance: send_stock_data.get_data scheduled__2024-07-28T12:55:00+00:00 [queued]>
[2024-07-28T13:01:55.577+0000] {taskinstance.py:2076} INFO - Dependencies all met for dep_context=requeueable deps ti=<TaskInstance: send_stock_data.get_data scheduled__2024-07-28T12:55:00+00:00 [queued]>
[2024-07-28T13:01:55.577+0000] {taskinstance.py:2306} INFO - Starting attempt 1 of 1
[2024-07-28T13:01:55.599+0000] {taskinstance.py:2330} INFO - Executing <Task(PythonOperator): get_data> on 2024-07-28 12:55:00+00:00
[2024-07-28T13:01:55.608+0000] {logging_mixin.py:188} WARNING - /home/***/.local/lib/python3.12/site-packages/***/task/task_runner/standard_task_runner.py:62 DeprecationWarning: This process (pid=742) is multi-threaded, use of fork() may lead to deadlocks in the child.
[2024-07-28T13:01:55.607+0000] {standard_task_runner.py:90} INFO - Running: ['***', 'tasks', 'run', 'send_stock_data', 'get_data', 'scheduled__2024-07-28T12:55:00+00:00', '--job-id', '14', '--raw', '--subdir', 'DAGS_FOLDER/***_stream.py', '--cfg-path', '/tmp/tmpz8sscuxo']
[2024-07-28T13:01:55.609+0000] {standard_task_runner.py:64} INFO - Started process 743 to run task
[2024-07-28T13:01:55.609+0000] {standard_task_runner.py:91} INFO - Job 14: Subtask get_data
[2024-07-28T13:01:55.627+0000] {logging_mixin.py:188} WARNING - /home/***/.local/lib/python3.12/site-packages/***/settings.py:195 DeprecationWarning: The sql_alchemy_conn option in [core] has been moved to the sql_alchemy_conn option in [database] - the old setting has been used, but please update your config.
[2024-07-28T13:01:55.670+0000] {task_command.py:426} INFO - Running <TaskInstance: send_stock_data.get_data scheduled__2024-07-28T12:55:00+00:00 [running]> on host 7cbb2ba4b48d
[2024-07-28T13:01:55.783+0000] {taskinstance.py:2648} INFO - Exporting env vars: AIRFLOW_CTX_DAG_OWNER='***' AIRFLOW_CTX_DAG_ID='send_stock_data' AIRFLOW_CTX_TASK_ID='get_data' AIRFLOW_CTX_EXECUTION_DATE='2024-07-28T12:55:00+00:00' AIRFLOW_CTX_TRY_NUMBER='1' AIRFLOW_CTX_DAG_RUN_ID='scheduled__2024-07-28T12:55:00+00:00'
[2024-07-28T13:01:55.785+0000] {taskinstance.py:430} INFO - ::endgroup::
[2024-07-28T13:01:55.807+0000] {taskinstance.py:441} INFO - ::group::Post task execution logs
[2024-07-28T13:01:55.808+0000] {taskinstance.py:2905} ERROR - Task failed with exception
Traceback (most recent call last):
  File "/home/airflow/.local/lib/python3.12/site-packages/urllib3/connection.py", line 203, in _new_conn
    sock = connection.create_connection(
           ^^^^^^^^^^^^^^^^^^^^^^^^^^^^^
  File "/home/airflow/.local/lib/python3.12/site-packages/urllib3/util/connection.py", line 60, in create_connection
    for res in socket.getaddrinfo(host, port, family, socket.SOCK_STREAM):
               ^^^^^^^^^^^^^^^^^^^^^^^^^^^^^^^^^^^^^^^^^^^^^^^^^^^^^^^^^^
  File "/usr/local/lib/python3.12/socket.py", line 964, in getaddrinfo
    for res in _socket.getaddrinfo(host, port, family, type, proto, flags):
               ^^^^^^^^^^^^^^^^^^^^^^^^^^^^^^^^^^^^^^^^^^^^^^^^^^^^^^^^^^^
socket.gaierror: [Errno -2] Name or service not known

The above exception was the direct cause of the following exception:

Traceback (most recent call last):
  File "/home/airflow/.local/lib/python3.12/site-packages/urllib3/connectionpool.py", line 791, in urlopen
    response = self._make_request(
               ^^^^^^^^^^^^^^^^^^^
  File "/home/airflow/.local/lib/python3.12/site-packages/urllib3/connectionpool.py", line 492, in _make_request
    raise new_e
  File "/home/airflow/.local/lib/python3.12/site-packages/urllib3/connectionpool.py", line 468, in _make_request
    self._validate_conn(conn)
  File "/home/airflow/.local/lib/python3.12/site-packages/urllib3/connectionpool.py", line 1097, in _validate_conn
    conn.connect()
  File "/home/airflow/.local/lib/python3.12/site-packages/urllib3/connection.py", line 611, in connect
    self.sock = sock = self._new_conn()
                       ^^^^^^^^^^^^^^^^
  File "/home/airflow/.local/lib/python3.12/site-packages/urllib3/connection.py", line 210, in _new_conn
    raise NameResolutionError(self.host, self, e) from e
urllib3.exceptions.NameResolutionError: <urllib3.connection.HTTPSConnection object at 0x7f995683f860>: Failed to resolve 'api.finnhub.io' ([Errno -2] Name or service not known)

The above exception was the direct cause of the following exception:

Traceback (most recent call last):
  File "/home/airflow/.local/lib/python3.12/site-packages/requests/adapters.py", line 667, in send
    resp = conn.urlopen(
           ^^^^^^^^^^^^^
  File "/home/airflow/.local/lib/python3.12/site-packages/urllib3/connectionpool.py", line 845, in urlopen
    retries = retries.increment(
              ^^^^^^^^^^^^^^^^^^
  File "/home/airflow/.local/lib/python3.12/site-packages/urllib3/util/retry.py", line 515, in increment
    raise MaxRetryError(_pool, url, reason) from reason  # type: ignore[arg-type]
    ^^^^^^^^^^^^^^^^^^^^^^^^^^^^^^^^^^^^^^^^^^^^^^^^^^^
urllib3.exceptions.MaxRetryError: HTTPSConnectionPool(host='api.finnhub.io', port=443): Max retries exceeded with url: /api/v1//quote?token=cqchq4pr01qoodgbgkbgcqchq4pr01qoodgbgkc0&symbol=AAPL (Caused by NameResolutionError("<urllib3.connection.HTTPSConnection object at 0x7f995683f860>: Failed to resolve 'api.finnhub.io' ([Errno -2] Name or service not known)"))

During handling of the above exception, another exception occurred:

Traceback (most recent call last):
  File "/home/airflow/.local/lib/python3.12/site-packages/airflow/models/taskinstance.py", line 465, in _execute_task
    result = _execute_callable(context=context, **execute_callable_kwargs)
             ^^^^^^^^^^^^^^^^^^^^^^^^^^^^^^^^^^^^^^^^^^^^^^^^^^^^^^^^^^^^^
  File "/home/airflow/.local/lib/python3.12/site-packages/airflow/models/taskinstance.py", line 432, in _execute_callable
    return execute_callable(context=context, **execute_callable_kwargs)
           ^^^^^^^^^^^^^^^^^^^^^^^^^^^^^^^^^^^^^^^^^^^^^^^^^^^^^^^^^^^^
  File "/home/airflow/.local/lib/python3.12/site-packages/airflow/models/baseoperator.py", line 401, in wrapper
    return func(self, *args, **kwargs)
           ^^^^^^^^^^^^^^^^^^^^^^^^^^^
  File "/home/airflow/.local/lib/python3.12/site-packages/airflow/operators/python.py", line 235, in execute
    return_value = self.execute_callable()
                   ^^^^^^^^^^^^^^^^^^^^^^^
  File "/home/airflow/.local/lib/python3.12/site-packages/airflow/operators/python.py", line 252, in execute_callable
    return self.python_callable(*self.op_args, **self.op_kwargs)
           ^^^^^^^^^^^^^^^^^^^^^^^^^^^^^^^^^^^^^^^^^^^^^^^^^^^^^
  File "/opt/airflow/dags/airflow_stream.py", line 34, in get_data
    quote_data = finnhub_client.quote('AAPL')
                 ^^^^^^^^^^^^^^^^^^^^^^^^^^^^
  File "/home/airflow/.local/lib/python3.12/site-packages/finnhub/client.py", line 205, in quote
    return self._get("/quote", params={
           ^^^^^^^^^^^^^^^^^^^^^^^^^^^^
  File "/home/airflow/.local/lib/python3.12/site-packages/finnhub/client.py", line 71, in _get
    return self._request("get", path, **kwargs)
           ^^^^^^^^^^^^^^^^^^^^^^^^^^^^^^^^^^^^
  File "/home/airflow/.local/lib/python3.12/site-packages/finnhub/client.py", line 40, in _request
    response = getattr(self._session, method)(uri, **kwargs)
               ^^^^^^^^^^^^^^^^^^^^^^^^^^^^^^^^^^^^^^^^^^^^^
  File "/home/airflow/.local/lib/python3.12/site-packages/requests/sessions.py", line 602, in get
    return self.request("GET", url, **kwargs)
           ^^^^^^^^^^^^^^^^^^^^^^^^^^^^^^^^^^
  File "/home/airflow/.local/lib/python3.12/site-packages/requests/sessions.py", line 589, in request
    resp = self.send(prep, **send_kwargs)
           ^^^^^^^^^^^^^^^^^^^^^^^^^^^^^^
  File "/home/airflow/.local/lib/python3.12/site-packages/requests/sessions.py", line 703, in send
    r = adapter.send(request, **kwargs)
        ^^^^^^^^^^^^^^^^^^^^^^^^^^^^^^^
  File "/home/airflow/.local/lib/python3.12/site-packages/requests/adapters.py", line 700, in send
    raise ConnectionError(e, request=request)
requests.exceptions.ConnectionError: HTTPSConnectionPool(host='api.finnhub.io', port=443): Max retries exceeded with url: /api/v1//quote?token=cqchq4pr01qoodgbgkbgcqchq4pr01qoodgbgkc0&symbol=AAPL (Caused by NameResolutionError("<urllib3.connection.HTTPSConnection object at 0x7f995683f860>: Failed to resolve 'api.finnhub.io' ([Errno -2] Name or service not known)"))
[2024-07-28T13:01:55.826+0000] {taskinstance.py:1206} INFO - Marking task as FAILED. dag_id=send_stock_data, task_id=get_data, run_id=scheduled__2024-07-28T12:55:00+00:00, execution_date=20240728T125500, start_date=20240728T130155, end_date=20240728T130155
[2024-07-28T13:01:55.840+0000] {standard_task_runner.py:110} ERROR - Failed to execute job 14 for task get_data (HTTPSConnectionPool(host='api.finnhub.io', port=443): Max retries exceeded with url: /api/v1//quote?token=cqchq4pr01qoodgbgkbgcqchq4pr01qoodgbgkc0&symbol=AAPL (Caused by NameResolutionError("<urllib3.connection.HTTPSConnection object at 0x7f995683f860>: Failed to resolve 'api.finnhub.io' ([Errno -2] Name or service not known)")); 743)
[2024-07-28T13:01:55.863+0000] {local_task_job_runner.py:243} INFO - Task exited with return code 1
[2024-07-28T13:01:55.891+0000] {taskinstance.py:3503} INFO - 0 downstream tasks scheduled from follow-on schedule check
[2024-07-28T13:01:55.899+0000] {local_task_job_runner.py:222} INFO - ::endgroup::
