[2024-07-30T14:41:00.142+0000] {local_task_job_runner.py:120} INFO - ::group::Pre task execution logs
[2024-07-30T14:41:00.193+0000] {taskinstance.py:2076} INFO - Dependencies all met for dep_context=non-requeueable deps ti=<TaskInstance: send_stock_data.format_data scheduled__2024-07-30T14:35:00+00:00 [queued]>
[2024-07-30T14:41:00.205+0000] {taskinstance.py:2076} INFO - Dependencies all met for dep_context=requeueable deps ti=<TaskInstance: send_stock_data.format_data scheduled__2024-07-30T14:35:00+00:00 [queued]>
[2024-07-30T14:41:00.206+0000] {taskinstance.py:2306} INFO - Starting attempt 1 of 1
[2024-07-30T14:41:00.236+0000] {taskinstance.py:2330} INFO - Executing <Task(PythonOperator): format_data> on 2024-07-30 14:35:00+00:00
[2024-07-30T14:41:00.246+0000] {logging_mixin.py:188} WARNING - /home/***/.local/lib/python3.12/site-packages/***/task/task_runner/standard_task_runner.py:62 DeprecationWarning: This process (pid=377) is multi-threaded, use of fork() may lead to deadlocks in the child.
[2024-07-30T14:41:00.248+0000] {standard_task_runner.py:64} INFO - Started process 379 to run task
[2024-07-30T14:41:00.246+0000] {standard_task_runner.py:90} INFO - Running: ['***', 'tasks', 'run', 'send_stock_data', 'format_data', 'scheduled__2024-07-30T14:35:00+00:00', '--job-id', '49', '--raw', '--subdir', 'DAGS_FOLDER/***_stream.py', '--cfg-path', '/tmp/tmpawj9injd']
[2024-07-30T14:41:00.249+0000] {standard_task_runner.py:91} INFO - Job 49: Subtask format_data
[2024-07-30T14:41:00.273+0000] {logging_mixin.py:188} WARNING - /home/***/.local/lib/python3.12/site-packages/***/settings.py:195 DeprecationWarning: The sql_alchemy_conn option in [core] has been moved to the sql_alchemy_conn option in [database] - the old setting has been used, but please update your config.
[2024-07-30T14:41:00.319+0000] {task_command.py:426} INFO - Running <TaskInstance: send_stock_data.format_data scheduled__2024-07-30T14:35:00+00:00 [running]> on host da3e94a6f80e
[2024-07-30T14:41:00.450+0000] {taskinstance.py:2648} INFO - Exporting env vars: AIRFLOW_CTX_DAG_OWNER='***' AIRFLOW_CTX_DAG_ID='send_stock_data' AIRFLOW_CTX_TASK_ID='format_data' AIRFLOW_CTX_EXECUTION_DATE='2024-07-30T14:35:00+00:00' AIRFLOW_CTX_TRY_NUMBER='1' AIRFLOW_CTX_DAG_RUN_ID='scheduled__2024-07-30T14:35:00+00:00'
[2024-07-30T14:41:00.452+0000] {taskinstance.py:430} INFO - ::endgroup::
[2024-07-30T14:41:00.614+0000] {taskinstance.py:441} INFO - ::group::Post task execution logs
[2024-07-30T14:41:00.615+0000] {taskinstance.py:2905} ERROR - Task failed with exception
Traceback (most recent call last):
  File "/home/airflow/.local/lib/python3.12/site-packages/pandas/core/indexes/base.py", line 3791, in get_loc
    return self._engine.get_loc(casted_key)
           ^^^^^^^^^^^^^^^^^^^^^^^^^^^^^^^^
  File "index.pyx", line 152, in pandas._libs.index.IndexEngine.get_loc
  File "index.pyx", line 181, in pandas._libs.index.IndexEngine.get_loc
  File "pandas/_libs/hashtable_class_helper.pxi", line 7080, in pandas._libs.hashtable.PyObjectHashTable.get_item
  File "pandas/_libs/hashtable_class_helper.pxi", line 7088, in pandas._libs.hashtable.PyObjectHashTable.get_item
KeyError: 'Datetime'

The above exception was the direct cause of the following exception:

Traceback (most recent call last):
  File "/home/airflow/.local/lib/python3.12/site-packages/airflow/models/taskinstance.py", line 465, in _execute_task
    result = _execute_callable(context=context, **execute_callable_kwargs)
             ^^^^^^^^^^^^^^^^^^^^^^^^^^^^^^^^^^^^^^^^^^^^^^^^^^^^^^^^^^^^^
  File "/home/airflow/.local/lib/python3.12/site-packages/airflow/models/taskinstance.py", line 432, in _execute_callable
    return execute_callable(context=context, **execute_callable_kwargs)
           ^^^^^^^^^^^^^^^^^^^^^^^^^^^^^^^^^^^^^^^^^^^^^^^^^^^^^^^^^^^^
  File "/home/airflow/.local/lib/python3.12/site-packages/airflow/models/baseoperator.py", line 401, in wrapper
    return func(self, *args, **kwargs)
           ^^^^^^^^^^^^^^^^^^^^^^^^^^^
  File "/home/airflow/.local/lib/python3.12/site-packages/airflow/operators/python.py", line 235, in execute
    return_value = self.execute_callable()
                   ^^^^^^^^^^^^^^^^^^^^^^^
  File "/home/airflow/.local/lib/python3.12/site-packages/airflow/operators/python.py", line 252, in execute_callable
    return self.python_callable(*self.op_args, **self.op_kwargs)
           ^^^^^^^^^^^^^^^^^^^^^^^^^^^^^^^^^^^^^^^^^^^^^^^^^^^^^
  File "/opt/airflow/dags/airflow_stream.py", line 55, in format_data
    'timestamp': record['Datetime'].isoformat(),
                 ~~~~~~^^^^^^^^^^^^
  File "/home/airflow/.local/lib/python3.12/site-packages/pandas/core/frame.py", line 3893, in __getitem__
    indexer = self.columns.get_loc(key)
              ^^^^^^^^^^^^^^^^^^^^^^^^^
  File "/home/airflow/.local/lib/python3.12/site-packages/pandas/core/indexes/base.py", line 3798, in get_loc
    raise KeyError(key) from err
KeyError: 'Datetime'
[2024-07-30T14:41:00.638+0000] {taskinstance.py:1206} INFO - Marking task as FAILED. dag_id=send_stock_data, task_id=format_data, run_id=scheduled__2024-07-30T14:35:00+00:00, execution_date=20240730T143500, start_date=20240730T144100, end_date=20240730T144100
[2024-07-30T14:41:00.658+0000] {standard_task_runner.py:110} ERROR - Failed to execute job 49 for task format_data ('Datetime'; 379)
[2024-07-30T14:41:00.704+0000] {local_task_job_runner.py:243} INFO - Task exited with return code 1
[2024-07-30T14:41:00.741+0000] {taskinstance.py:3503} INFO - 0 downstream tasks scheduled from follow-on schedule check
[2024-07-30T14:41:00.751+0000] {local_task_job_runner.py:222} INFO - ::endgroup::
